func throw_exception() => throw Exception("Oops");

func main() {
    try {
        println(foo());
        try {
        } catch error1 {
            try {
                println(foo());
            } catch error2 {
                println(foo());
            }
        }
    } catch error {
        println(error);
    }

    var a = try 2 * 10;
    assert(a == 20);
    a = try throw_exception();
    assert(typeof(a) == Exception);
}

func foo() => bar();
func bar() => baz();
func baz() => faz();
func faz() => boo();
func boo() => "Hello" / 2;
